<?xml version="1.0" ?>
<!-- =================================================================================== -->
<!-- |    This document was autogenerated by xacro from src/motoman_motomini_support/urdf/motomini.xacro | -->
<!-- |    EDITING THIS FILE BY HAND IS NOT RECOMMENDED                                 | -->
<!-- =================================================================================== -->
<robot name="motoman_motomini">
  <!-- link list -->
  <link name="base_link">
    <visual>
      <geometry>
        <mesh filename="package://motoman_motomini_support/meshes/motomini/visual/base_link.stl"/>
      </geometry>
      <material name="">
        <color rgba="0.12941176470588237 0.14901960784313725 0.7490196078431373 1.0"/>
      </material>
    </visual>
    <collision>
      <geometry>
        <mesh filename="package://motoman_motomini_support/meshes/motomini/collision/base_link.stl"/>
      </geometry>
    </collision>
  </link>
  <link name="link_1_s">
    <visual>
      <geometry>
        <mesh filename="package://motoman_motomini_support/meshes/motomini/visual/link_1_s.stl"/>
      </geometry>
      <material name="">
        <color rgba="0.12941176470588237 0.14901960784313725 0.7490196078431373 1.0"/>
      </material>
    </visual>
    <collision>
      <geometry>
        <mesh filename="package://motoman_motomini_support/meshes/motomini/collision/link_1_s.stl"/>
      </geometry>
    </collision>
  </link>
  <link name="link_2_l">
    <visual>
      <geometry>
        <mesh filename="package://motoman_motomini_support/meshes/motomini/visual/link_2_l.stl"/>
      </geometry>
      <material name="">
        <color rgba="0.12941176470588237 0.14901960784313725 0.7490196078431373 1.0"/>
      </material>
    </visual>
    <collision>
      <geometry>
        <mesh filename="package://motoman_motomini_support/meshes/motomini/collision/link_2_l.stl"/>
      </geometry>
    </collision>
  </link>
  <link name="link_3_u">
    <visual>
      <geometry>
        <mesh filename="package://motoman_motomini_support/meshes/motomini/visual/link_3_u.stl"/>
      </geometry>
      <material name="">
        <color rgba="0.12941176470588237 0.14901960784313725 0.7490196078431373 1.0"/>
      </material>
    </visual>
    <collision>
      <geometry>
        <mesh filename="package://motoman_motomini_support/meshes/motomini/collision/link_3_u.stl"/>
      </geometry>
    </collision>
  </link>
  <link name="link_4_r">
    <visual>
      <geometry>
        <mesh filename="package://motoman_motomini_support/meshes/motomini/visual/link_4_r.stl"/>
      </geometry>
      <material name="">
        <color rgba="0.12941176470588237 0.14901960784313725 0.7490196078431373 1.0"/>
      </material>
    </visual>
    <collision>
      <geometry>
        <mesh filename="package://motoman_motomini_support/meshes/motomini/collision/link_4_r.stl"/>
      </geometry>
    </collision>
  </link>
  <link name="link_5_b">
    <visual>
      <geometry>
        <mesh filename="package://motoman_motomini_support/meshes/motomini/visual/link_5_b.stl"/>
      </geometry>
      <material name="">
        <color rgba="0.12941176470588237 0.14901960784313725 0.7490196078431373 1.0"/>
      </material>
    </visual>
    <collision>
      <geometry>
        <mesh filename="package://motoman_motomini_support/meshes/motomini/collision/link_5_b.stl"/>
      </geometry>
    </collision>
  </link>
  <link name="link_6_t">
    <visual>
      <geometry>
        <mesh filename="package://motoman_motomini_support/meshes/motomini/visual/link_6_t.stl"/>
      </geometry>
      <material name="">
        <color rgba="0.12941176470588237 0.14901960784313725 0.7490196078431373 1.0"/>
      </material>
    </visual>
    <collision>
      <geometry>
        <mesh filename="package://motoman_motomini_support/meshes/motomini/collision/link_6_t.stl"/>
      </geometry>
    </collision>
  </link>
  <link name="tool0"/>
  <!-- end of link list -->
  <!-- joint list -->
  <joint name="joint_1_s" type="revolute">
    <parent link="base_link"/>
    <child link="link_1_s"/>
    <origin rpy="0 0 0" xyz="0 0 0.103"/>
    <axis xyz="0 0 1"/>
    <limit effort="0.12" lower="-2.9670" upper="2.9670" velocity="5.4977"/>
  </joint>
  <joint name="joint_2_l" type="revolute">
    <parent link="link_1_s"/>
    <child link="link_2_l"/>
    <origin rpy="0 0 0" xyz="0.020 0 0"/>
    <axis xyz="0 1 0"/>
    <limit effort="0.12" lower="-1.4835" upper="1.5707" velocity="5.4977"/>
  </joint>
  <joint name="joint_3_u" type="revolute">
    <parent link="link_2_l"/>
    <child link="link_3_u"/>
    <origin rpy="0 0 0" xyz="0 0 0.165"/>
    <axis xyz="0 -1 0"/>
    <limit effort="0.12" lower="-0.8726" upper="1.5707" velocity="7.3304"/>
  </joint>
  <joint name="joint_4_r" type="revolute">
    <parent link="link_3_u"/>
    <child link="link_4_r"/>
    <origin rpy="0 0 0" xyz="0.165 0 0"/>
    <axis xyz="-1 0 0"/>
    <limit effort="0.07" lower="-2.4434" upper="2.4434" velocity="10.4719"/>
  </joint>
  <joint name="joint_5_b" type="revolute">
    <parent link="link_4_r"/>
    <child link="link_5_b"/>
    <origin rpy="0 0 0" xyz="0 0 0"/>
    <axis xyz="0 -1 0"/>
    <limit effort="0.07" lower="-0.5235" upper="3.6651" velocity="10.4719"/>
  </joint>
  <joint name="joint_6_t" type="revolute">
    <parent link="link_5_b"/>
    <child link="link_6_t"/>
    <origin rpy="0 0 0" xyz="0 0 0"/>
    <axis xyz="0 0 1"/>
    <limit effort="0.07" lower="-6.2831" upper="6.2831" velocity="10.4719"/>
  </joint>
  <joint name="joint_6_t-tool0" type="fixed">
    <origin rpy="3.141592653589793 0 0" xyz="0 0 -0.040 "/>
    <parent link="link_6_t"/>
    <child link="tool0"/>
  </joint>
  <!-- end of joint list -->
  <!-- ROS base_link to Robot Manufacturer World Coordinates transform -->
  <link name="base"/>
  <joint name="base_link-base" type="fixed">
    <origin rpy="0 0 0" xyz="0 0 0.103"/>
    <parent link="base_link"/>
    <child link="base"/>
  </joint>
</robot>
